Workbook

Sheet Ringkasan
A1: Estimasi Mandays Pengembangan
A2: Modul Kontrak (Spesifik/Payung), Release Order, Penawaran, Customer PO, Site/Presensi GPS, Tanda Tangan Digital
A3: PT RTN -- Sistem Project Management | Estimasi bila dikerjakan tim developer tanpa bantuan AI
A5: RINGKASAN ANGKA
A6: Total Estimasi Mandays (seluruh tim) | B6: md | C6: ='Rekap per Role'!B11 -> 114
A7: Jumlah Task/Deliverable Teridentifikasi | B7: task | C7: =COUNTA('Rincian Task'!A3:A43) -> 41
A8: Estimasi Durasi Kalender (tim inti 6 orang, ada overlap antar fase) | C8: 10-11 minggu (± 2.5 bulan)
A9: Estimasi Durasi Kalender (tanpa overlap, fase strict berurutan) | B9: minggu | C9: =Timeline!E10 -> 13
A11: KOMPOSISI TIM REKOMENDASI
A12: Role | B12: Alokasi | C12: Total Mandays | D12: Catatan Peran
A13: Tech Lead / Senior Developer | B13: 100% (full-time) | C13: =SUMIF('Rincian Task'!$D$3:$D$43,A13,'Rincian Task'!$E$3:$E$43) -> 26 | D13: Arsitektur, migrasi berisiko, modul Penawaran (paling kompleks), review kode
A14: Backend Developer | B14: 100% (full-time) | C14: =SUMIF('Rincian Task'!$D$3:$D$43,A14,'Rincian Task'!$E$3:$E$43) -> 17 | D14: Model, migration, business logic pendukung
A15: Fullstack Developer (Livewire) | B15: 2 orang x 100% (full-time) | C15: =SUMIF('Rincian Task'!$D$3:$D$43,A15,'Rincian Task'!$E$3:$E$43) -> 46 | D15: Seluruh modul UI: Contract, RO, CustomerPO, Site, Presensi, Tanda Tangan
A16: QA / Tester | B16: 100% (full-time, mulai penuh di Fase 3) | C16: =SUMIF('Rincian Task'!$D$3:$D$43,A16,'Rincian Task'!$E$3:$E$43) -> 12 | D16: Test case, functional & regression testing, dampingi UAT
A17: Business Analyst | B17: ~40% (paruh waktu, padat di Fase 0 & 4) | C17: =SUMIF('Rincian Task'!$D$3:$D$43,A17,'Rincian Task'!$E$3:$E$43) -> 8 | D17: Requirement, dokumentasi, training user
A18: UI/UX Designer | B18: ~20% (paruh waktu, hanya Fase 0) | C18: =SUMIF('Rincian Task'!$D$3:$D$43,A18,'Rincian Task'!$E$3:$E$43) -> 5 | D18: Wireframe/mockup layar baru
A19: TOTAL | C19: =SUM(C13:C18) -> 114
A21: CATATAN & ASUMSI
A22: • 1 manday = 1 orang bekerja 1 hari efektif (~7 jam), 5 hari kerja/minggu.
A23: • Estimasi disusun berdasarkan cakupan fitur yang sudah didiskusikan & dibangun sebagai prototipe di sesi ini (12 entity baru, 4 entity existing yang disesuaikan, modul Presensi GPS, dan Tanda Tangan Digital).
A24: • Sudah termasuk regression testing modul Purchasing/RFQ existing, karena skema tabel request_for_quotations ikut berubah (kolom project_id dibuat nullable + constraint baru) -- ini titik risiko utama proyek.
A25: • Durasi kalender TIDAK sama dengan total mandays dibagi jumlah orang, karena ada dependency antar fase (desain -> backend -> frontend -> QA) yang membatasi paralelisasi penuh.
A26: • Belum termasuk: lisensi/biaya infrastruktur, kontinjensi khusus untuk perubahan scope di tengah jalan, dan biaya tarif harian (isi sendiri di sheet 'Rekap per Role' sesuai standar internal perusahaan).
A27: • Tim lebih kecil (mis. 3-4 orang merangkap beberapa peran) akan memperpanjang durasi kalender secara proporsional, meski total mandays tetap sama.

Sheet Rincian Task
A1: Rincian Task & Estimasi Mandays per Fase
A2: No | B2: Fase | C2: Task / Deliverable | D2: Role | E2: Mandays | F2: Catatan
A3: 1 | B3: Fase 0 - Analisa & Desain | C3: Analisa proses bisnis & penyusunan functional spec | D3: Business Analyst | E3: 4
A4: 2 | B4: Fase 0 - Analisa & Desain | C4: Desain ERD / skema database (12 tabel baru + perubahan tabel existing) | D4: Tech Lead / Senior Developer | E4: 3
A5: 3 | B5: Fase 0 - Analisa & Desain | C5: Desain arsitektur teknis & mitigasi risiko (migrasi data live, RFQ dual-context, backward-compatibility) | D5: Tech Lead / Senior Developer | E5: 3 | F5: Risiko tinggi: menyentuh tabel Purchasing yang sudah dipakai produksi
A6: 4 | B6: Fase 0 - Analisa & Desain | C6: Wireframe & UI mockup seluruh layar baru | D6: UI/UX Designer | E6: 5
A7: 5 | B7: Fase 0 - Analisa & Desain | C7: Review & sign-off desain dengan stakeholder (Direktur/Project Controller) | D7: Business Analyst | E7: 1
A8: 6 | B8: Fase 0 - Analisa & Desain | C8: Review & sign-off desain dengan stakeholder (Direktur/Project Controller) | D8: Tech Lead / Senior Developer | E8: 1
A9: 7 | B9: Fase 1 - Backend Foundation | C9: Migration 12 tabel baru + 4 alter tabel existing | D9: Tech Lead / Senior Developer | E9: 4 | F9: Termasuk kolom nullable + CHECK constraint pada tabel RFQ existing
A10: 8 | B10: Fase 1 - Backend Foundation | C10: Model inti: Customer, Contract (tracking nilai terpakai/sisa plafon), Site (geofencing) | D10: Backend Developer | E10: 3
A11: 9 | B11: Fase 1 - Backend Foundation | C11: Model: ReleaseOrder + ReleaseOrderItem | D11: Backend Developer | E11: 2
A12: 10 | B12: Fase 1 - Backend Foundation | C12: Model & state machine: CustomerQuotation + Item (draft-submit-approve-reject-revisi) | D12: Tech Lead / Senior Developer | E12: 4
A13: 11 | B13: Fase 1 - Backend Foundation | C13: Model: CustomerPurchaseOrder (auto convert ke Project), ProjectBudgetLine | D13: Backend Developer | E13: 3
A14: 12 | B14: Fase 1 - Backend Foundation | C14: Model: Attendance, UserSignature, DocumentSignature (polymorphic) | D14: Backend Developer | E14: 3
A15: 13 | B15: Fase 1 - Backend Foundation | C15: Penyesuaian model existing: Project, Activity, Assignment | D15: Backend Developer | E15: 2
A16: 14 | B16: Fase 1 - Backend Foundation | C16: Penyesuaian RequestForQuotation jadi dual-context (procurement vs costing) | D16: Tech Lead / Senior Developer | E16: 3 | F16: Berisiko regresi ke modul Purchasing yang sudah berjalan
A17: 15 | B17: Fase 1 - Backend Foundation | C17: Role & permission baru + penyesuaian access matrix | D17: Backend Developer | E17: 1
A18: 16 | B18: Fase 2 - Modul Fitur (UI/Livewire) | C18: Modul Kelola Customer (CRUD) | D18: Fullstack Developer (Livewire) | E18: 2
A19: 17 | B19: Fase 2 - Modul Fitur (UI/Livewire) | C19: Modul Kelola Contract (CRUD, detail, plafon, multi-site, upload dokumen) | D19: Fullstack Developer (Livewire) | E19: 4
A20: 18 | B20: Fase 2 - Modul Fitur (UI/Livewire) | C20: Modul Release Order (buat dari kontrak, item CRUD, status, edit/batalkan/hapus) | D20: Fullstack Developer (Livewire) | E20: 4
A21: 19 | B21: Fase 2 - Modul Fitur (UI/Livewire) | C21: Penyesuaian UI modul RFQ existing (dual-context procurement vs costing) | D21: Fullstack Developer (Livewire) | E21: 3
A22: 20 | B22: Fase 2 - Modul Fitur (UI/Livewire) | C22: Modul Penawaran/CustomerQuotation (item builder, revisi, approval Direktur, keputusan customer) | D22: Tech Lead / Senior Developer | E22: 5 | F22: Modul komersial paling kompleks
A23: 21 | B23: Fase 2 - Modul Fitur (UI/Livewire) | C23: Modul CustomerPurchaseOrder (terima PO, convert ke Project + budget breakdown) | D23: Fullstack Developer (Livewire) | E23: 3
A24: 22 | B24: Fase 2 - Modul Fitur (UI/Livewire) | C24: Breakdown budget Project per kategori + laporan realisasi | D24: Fullstack Developer (Livewire) | E24: 3
A25: 23 | B25: Fase 2 - Modul Fitur (UI/Livewire) | C25: Modul Site/Lokasi (CRUD + picker peta lat/long) | D25: Fullstack Developer (Livewire) | E25: 3
A26: 24 | B26: Fase 2 - Modul Fitur (UI/Livewire) | C26: Modul Presensi Teknisi (check-in geolocation, validasi radius, hard-block) | D26: Fullstack Developer (Livewire) | E26: 3
A27: 25 | B27: Fase 2 - Modul Fitur (UI/Livewire) | C27: Modul Override Presensi (Admin/PM + audit trail) | D27: Fullstack Developer (Livewire) | E27: 2
A28: 26 | B28: Fase 2 - Modul Fitur (UI/Livewire) | C28: Integrasi wajib-presensi ke Submit Laporan | D28: Fullstack Developer (Livewire) | E28: 1
A29: 27 | B29: Fase 2 - Modul Fitur (UI/Livewire) | C29: Modul Tanda Tangan Digital (canvas + upload + kelola default + serving file aman) | D29: Fullstack Developer (Livewire) | E29: 3
A30: 28 | B30: Fase 2 - Modul Fitur (UI/Livewire) | C30: Integrasi tanda tangan ke dokumen Penawaran | D30: Fullstack Developer (Livewire) | E30: 2
A31: 29 | B31: Fase 2 - Modul Fitur (UI/Livewire) | C31: Dashboard/widget ringkasan kontrak & plafon | D31: Fullstack Developer (Livewire) | E31: 2
A32: 30 | B32: Fase 2 - Modul Fitur (UI/Livewire) | C32: Navigasi, permission-gating UI, polish tampilan | D32: Fullstack Developer (Livewire) | E32: 2
A33: 31 | B33: Fase 3 - QA & Testing | C33: Penyusunan test case (functional + regresi) | D33: QA / Tester | E33: 3
A34: 32 | B34: Fase 3 - QA & Testing | C34: Functional testing seluruh modul baru | D34: QA / Tester | E34: 6
A35: 33 | B35: Fase 3 - QA & Testing | C35: Regression testing modul existing (Purchasing, RFQ, PO, Project, KPI) | D35: QA / Tester | E35: 3 | F35: Wajib karena skema tabel Purchasing berubah
A36: 34 | B36: Fase 3 - QA & Testing | C36: Bug fixing hasil temuan QA | D36: Backend Developer | E36: 3
A37: 35 | B37: Fase 3 - QA & Testing | C37: Bug fixing hasil temuan QA | D37: Fullstack Developer (Livewire) | E37: 3
A38: 36 | B38: Fase 3 - QA & Testing | C38: UAT bersama user (iteratif, proses bisnis komersial biasanya banyak revisi) | D38: Fullstack Developer (Livewire) | E38: 3
A39: 37 | B39: Fase 3 - QA & Testing | C39: Perbaikan hasil UAT | D39: Fullstack Developer (Livewire) | E39: 3
A40: 38 | B40: Fase 4 - Deployment & Dokumentasi | C40: Migration rehearsal di staging (copy DB produksi) + rollback plan | D40: Tech Lead / Senior Developer | E40: 2
...

Sheet Rekap per Role
A1: Rekap Mandays & Estimasi Biaya per Role
A2: Isi kolom 'Tarif per Manday (Rp)' (sel kuning) sesuai standar rate internal perusahaan Anda.
A4: Role | B4: Total Mandays | C4: Tarif per Manday (Rp) | D4: Total Estimasi Biaya (Rp)
A5: Tech Lead / Senior Developer | B5: =SUMIF('Rincian Task'!$D$3:$D$43,A5,'Rincian Task'!$E$3:$E$43) -> 26 | C5: 0 | D5: =B5*C5 -> 0
A6: Backend Developer | B6: =SUMIF('Rincian Task'!$D$3:$D$43,A6,'Rincian Task'!$E$3:$E$43) -> 17 | C6: 0 | D6: =B6*C6 -> 0
A7: Fullstack Developer (Livewire) | B7: =SUMIF('Rincian Task'!$D$3:$D$43,A7,'Rincian Task'!$E$3:$E$43) -> 46 | C7: 0 | D7: =B7*C7 -> 0
A8: QA / Tester | B8: =SUMIF('Rincian Task'!$D$3:$D$43,A8,'Rincian Task'!$E$3:$E$43) -> 12 | C8: 0 | D8: =B8*C8 -> 0
A9: Business Analyst | B9: =SUMIF('Rincian Task'!$D$3:$D$43,A9,'Rincian Task'!$E$3:$E$43) -> 8 | C9: 0 | D9: =B9*C9 -> 0
A10: UI/UX Designer | B10: =SUMIF('Rincian Task'!$D$3:$D$43,A10,'Rincian Task'!$E$3:$E$43) -> 5 | C10: 0 | D10: =B10*C10 -> 0
A11: TOTAL | B11: =SUM(B5:B10) -> 114 | D11: =SUM(D5:D10) -> 0
A13: Catatan: Total Mandays di sini ditarik otomatis (SUMIF) dari sheet 'Rincian Task'. Tarif per manday TIDAK diisi otomatis -- silakan sesuaikan dengan standar gaji/vendor rate perusahaan.

Sheet Timeline
A1: Timeline Estimasi per Fase
A2: Asumsi tim inti: 1 Tech Lead + 1 Backend Developer + 2 Fullstack Developer + 1 QA (+ BA & UI/UX paruh waktu)
A4: Fase | B4: Deskripsi Singkat | C4: Role Terlibat | D4: Mandays Fase | E4: Estimasi Durasi Kalender (minggu)
A5: Fase 0 - Analisa & Desain | B5: Functional spec, ERD, arsitektur teknis, wireframe, sign-off | C5: BA, Tech Lead, UI/UX Designer | D5: =SUMIF('Rincian Task'!$B$3:$B$43,A5,'Rincian Task'!$E$3:$E$43) -> 17 | E5: 2
A6: Fase 1 - Backend Foundation | B6: Migration, model, state machine, RBAC | C6: Tech Lead, Backend Developer | D6: =SUMIF('Rincian Task'!$B$3:$B$43,A6,'Rincian Task'!$E$3:$E$43) -> 25 | E6: 3
A7: Fase 2 - Modul Fitur (UI/Livewire) | B7: Seluruh modul: Customer, Contract, RO, Penawaran, CustomerPO, Site, Presensi, Tanda Tangan | C7: Tech Lead, Fullstack Developer x2 | D7: =SUMIF('Rincian Task'!$B$3:$B$43,A7,'Rincian Task'!$E$3:$E$43) -> 42 | E7: 4
A8: Fase 3 - QA & Testing | B8: Test case, functional & regression testing, bug fixing, UAT | C8: QA, Backend Developer, Fullstack Developer | D8: =SUMIF('Rincian Task'!$B$3:$B$43,A8,'Rincian Task'!$E$3:$E$43) -> 24 | E8: 3
A9: Fase 4 - Deployment & Dokumentasi | B9: Migration rehearsal, deployment produksi, dokumentasi, training | C9: Tech Lead, Business Analyst | D9: =SUMIF('Rincian Task'!$B$3:$B$43,A9,'Rincian Task'!$E$3:$E$43) -> 6 | E9: 1
A10: TOTAL (bila fase berurutan penuh, tanpa overlap) | D10: =SUM(D5:D9) -> 114 | E10: =SUM(E5:E9) -> 13
A12: Catatan: 13 minggu di atas asumsi fase berjalan strict berurutan (worst case). Dengan overlap wajar (mis. QA mulai smoke test modul yang sudah selesai sementara fase 2 masih berjalan di modul lain, dokumentasi berjalan paralel dengan testing), durasi realistis untuk tim 6 orang adalah 10-11 minggu.
