Workbook

Sheet Ringkasan
A1: Estimasi Mandays Pengembangan -- SRS v2.0
A2: Company Digital Office System -- 22 Modul, 13 Role, 3 Portal (External Website, Client Portal, Internal Portal)
A3: PT RTN | Estimasi bila dikerjakan tim developer tanpa bantuan AI | Superseded: estimasi kontrak-payung sebelumnya (114 md) kini bagian dari Fase 1
A5: RINGKASAN ANGKA
A6: Total Estimasi Mandays (termasuk overhead PM) | B6: md | C6: ='Rekap per Role'!B14 -> 462
A7: Jumlah Task/Deliverable Teridentifikasi | B7: task | C7: =COUNTA('Rincian Modul'!A3:A61) -> 59
A8: Estimasi Durasi Kalender (tim inti ~9-10 orang, fase overlap wajar) | C8: 8-9 bulan
A9: Estimasi Durasi Kalender (tanpa overlap, fase strict berurutan) | B9: minggu | C9: =Timeline!E12 -> 28
A11: KOMPOSISI TIM REKOMENDASI
A12: Role | B12: Alokasi | C12: Total Mandays | D12: Catatan Peran
A13: Project Manager (Delivery) | B13: 100% sepanjang proyek (~9 bulan) | C13: =SUMIF('Rincian Modul'!$D$3:$D$61,A13,'Rincian Modul'!$E$3:$E$61) -> 42 | D13: Koordinasi, status report mingguan, change request, komunikasi stakeholder
A14: Tech Lead / Senior Developer | B14: 100% sepanjang proyek | C14: =SUMIF('Rincian Modul'!$D$3:$D$61,A14,'Rincian Modul'!$E$3:$E$61) -> 109 | D14: Arsitektur, modul Finance/Payroll, rekonsiliasi dgn sistem existing, review kode
A15: Backend Developer | B15: 100%, terkonsentrasi di Fase 1 | C15: =SUMIF('Rincian Modul'!$D$3:$D$61,A15,'Rincian Modul'!$E$3:$E$61) -> 36 | D15: Bisa merangkap Fullstack Developer di fase lain untuk efisiensi biaya
A16: Fullstack Developer (Livewire) | B16: 2-3 orang x 100% | C16: =SUMIF('Rincian Modul'!$D$3:$D$61,A16,'Rincian Modul'!$E$3:$E$61) -> 170 | D16: Beban terbesar (170 md) -- modul UI/Livewire tersebar di semua fase
A17: Frontend/Web Developer | B17: Part-time/project-based (~1 bulan) | C17: =SUMIF('Rincian Modul'!$D$3:$D$61,A17,'Rincian Modul'!$E$3:$E$61) -> 18 | D17: Hanya intensif di Fase 4 (External Website)
A18: UI/UX Designer | B18: Part-time (~3 minggu, terutama Fase 0) | C18: =SUMIF('Rincian Modul'!$D$3:$D$61,A18,'Rincian Modul'!$E$3:$E$61) -> 15 | D18: Wireframe/mockup seluruh layar baru
A19: QA / Tester | B19: 1-2 orang, penuh mulai Fase 5 | C19: =SUMIF('Rincian Modul'!$D$3:$D$61,A19,'Rincian Modul'!$E$3:$E$61) -> 38 | D19: Disarankan terlibat sejak Fase 1 untuk smoke test incremental
A20: Business Analyst | B20: Part-time sepanjang proyek | C20: =SUMIF('Rincian Modul'!$D$3:$D$61,A20,'Rincian Modul'!$E$3:$E$61) -> 22 | D20: Padat di Fase 0 (requirement) & Fase 6 (dokumentasi/training)
A21: DevOps / Infrastructure | B21: Part-time, terutama Fase 6 | C21: =SUMIF('Rincian Modul'!$D$3:$D$61,A21,'Rincian Modul'!$E$3:$E$61) -> 12 | D21: Infrastruktur, CI/CD, deployment, monitoring
A22: TOTAL | C22: =SUM(C13:C21) -> 462
A24: CATATAN & ASUMSI PENTING
A25: • Estimasi ini SUPERSEDE estimasi sebelumnya (114 md, khusus modul kontrak payung/spesifik) -- scope SRS v2.0 jauh lebih besar (22 modul, 13 role, 3 portal) dan kini mencakup pekerjaan itu di dalam Fase 1.
A26: • 4 TEMUAN KRITIS dari analisa gap (lihat dok 'perbandingan-srs-v2-vs-sistem-existing') BELUM terjawab saat estimasi ini dibuat, dan mempengaruhi akurasi Fase 1 & Fase 2: (1) role 'Project Controller' yang sudah dibangun vs 'Project Control' di SRS beda fungsi; (2) istilah kontrak spesifik/payung & alur Release Order tidak muncul eksplisit di SRS; (3) kebutuhan e-signature bersertifikat (PSrE/Peruri) vs in-house yang sudah dibangun; (4) hierarki data Unit (existing) vs Client/Lokasi (SRS). Rekomendasi: konfirmasi dulu sebelum kontrak ditandatangani -- lihat baris bercatatan di sheet 'Rincian Modul'.
A27: • 1 manday = 1 orang bekerja 1 hari efektif (~7 jam), 5 hari kerja/minggu.
A28: • Overhead Project Management dihitung otomatis 10% dari total mandays teknis (baris terakhir di 'Rincian Modul').
A29: • Belum termasuk: lisensi/biaya hosting & infrastruktur cloud (tergantung pilihan provider), kontinjensi perubahan scope di tengah jalan, dan tarif harian (isi sendiri di sheet 'Rekap per Role').
A30: • Modul yang sudah berjalan di sistem existing (Project Management, Purchasing & Material Tracking, KPI & Work Log, Auth dasar) diberi porsi mandays jauh lebih kecil karena tinggal penyesuaian, bukan dibangun dari nol.

Sheet Rincian Modul
A1: Rincian Modul & Estimasi Mandays per Fase (SRS v2.0)
A2: No | B2: Fase | C2: Modul / Task | D2: Role | E2: Mandays | F2: Catatan
A3: 1 | B3: Fase 0 - Analisa & Desain | C3: Analisa proses bisnis & functional spec 22 modul, 13 role, 3 portal | D3: Business Analyst | E3: 10
A4: 2 | B4: Fase 0 - Analisa & Desain | C4: Desain ERD lengkap (seluruh modul, termasuk integrasi dgn skema existing) | D4: Tech Lead / Senior Developer | E4: 8
A5: 3 | B5: Fase 0 - Analisa & Desain | C5: Desain arsitektur 3 portal (shared authentication, isolasi data eksternal/internal) | D5: Tech Lead / Senior Developer | E5: 6
A6: 4 | B6: Fase 0 - Analisa & Desain | C6: Wireframe/mockup: login, dashboard (min 7 role), external website, client portal, form BOQ/Penawaran, invoice, kasbon, admin user management | D6: UI/UX Designer | E6: 15 | F6: Wajib dilampirkan di proposal vendor sesuai SRS bab 7.1
A7: 5 | B7: Fase 0 - Analisa & Desain | C7: Tech stack justification & dokumen rencana proyek | D7: Tech Lead / Senior Developer | E7: 2
A8: 6 | B8: Fase 0 - Analisa & Desain | C8: Review & sign-off desain dengan stakeholder | D8: Business Analyst | E8: 1
A9: 7 | B9: Fase 0 - Analisa & Desain | C9: Review & sign-off desain dengan stakeholder | D9: Tech Lead / Senior Developer | E9: 1
A10: 8 | B10: Fase 1 - Fondasi & Divisi 2 (Service & Maintenance) | C10: Role & permission sesuai 13 role SRS (pemisahan Project Control vs Project Controller, Cost Control, Lead Technician, Admin, dll) | D10: Backend Developer | E10: 4 | F10: Perlu klarifikasi dulu -- lihat temuan 3.1 di analisa gap
A11: 9 | B11: Fase 1 - Fondasi & Divisi 2 (Service & Maintenance) | C11: Penyesuaian Authentication & User Management (audit log login, bulk import CSV/Excel) | D11: Backend Developer | E11: 6
A12: 10 | B12: Fase 1 - Fondasi & Divisi 2 (Service & Maintenance) | C12: Master Sparepart/Material terstruktur per Tipe Pompa + Engine + Serial Number | D12: Backend Developer | E12: 5
A13: 11 | B13: Fase 1 - Fondasi & Divisi 2 (Service & Maintenance) | C13: Master Unit Pompa (Aset Klien): serial number, riwayat service, kondisi terakhir | D13: Fullstack Developer (Livewire) | E13: 6
A14: 12 | B14: Fase 1 - Fondasi & Divisi 2 (Service & Maintenance) | C14: Penyesuaian Master Client & Vendor (field tambahan) | D14: Backend Developer | E14: 3
A15: 13 | B15: Fase 1 - Fondasi & Divisi 2 (Service & Maintenance) | C15: Rekonsiliasi hierarki data: Unit (existing) vs Client/Lokasi (SRS) + migrasi data | D15: Tech Lead / Senior Developer | E15: 5 | F15: Lihat temuan 3.4 di analisa gap
A16: 14 | B16: Fase 1 - Fondasi & Divisi 2 (Service & Maintenance) | C16: Rekonsiliasi alur Kontrak Payung/RO/CustomerQuotation (existing) vs alur BOQ & Penawaran / BAPP RO (SRS 5.1) | D16: Tech Lead / Senior Developer | E16: 5 | F16: Lihat temuan 3.2 -- keputusan arsitektur penting, sebaiknya dikonfirmasi dulu
A17: 15 | B17: Fase 1 - Fondasi & Divisi 2 (Service & Maintenance) | C17: Penyesuaian Project Management: hierarki Region->Client/Lokasi->Kontrak->Proyek->Activity/Checkpoint, 5 tipe proyek | D17: Tech Lead / Senior Developer | E17: 8
A18: 16 | B18: Fase 1 - Fondasi & Divisi 2 (Service & Maintenance) | C18: Assignment & Scheduling 2-tahap (Lead Technician usul, PM/Project Control approve), request safetyman/admin lokasi | D18: Fullstack Developer (Livewire) | E18: 8
A19: 17 | B19: Fase 1 - Fondasi & Divisi 2 (Service & Maintenance) | C19: Operasional Lapangan & Laporan Teknisi (Safety Talk/Toolbox log, jam kerja terstruktur, link Kasbon/Expense, Simlok/SIKA H-3) | D19: Fullstack Developer (Livewire) | E19: 10
A20: 18 | B20: Fase 1 - Fondasi & Divisi 2 (Service & Maintenance) | C20: Document Management terstruktur (folder taxonomy, matriks akses, versioning, preview inline, bulk download zip) | D20: Fullstack Developer (Livewire) | E20: 14
A21: 19 | B21: Fase 1 - Fondasi & Divisi 2 (Service & Maintenance) | C21: BOQ & Penawaran Service & Maintenance (filter item per tipe pompa/engine/SN, approval PM/Direktur) | D21: Tech Lead / Senior Developer | E21: 10 | F21: Berpotensi tumpang-tindih dgn modul existing -- lihat temuan 3.2
A22: 20 | B22: Fase 1 - Fondasi & Divisi 2 (Service & Maintenance) | C22: Penyesuaian Purchasing & Material Tracking (reminder H-7) | D22: Backend Developer | E22: 4
A23: 21 | B23: Fase 1 - Fondasi & Divisi 2 (Service & Maintenance) | C23: Admin Operasional (Admin Kantor: rekap, BAPP, BAL; Admin Purchase: surat jalan, gatepass) | D23: Fullstack Developer (Livewire) | E23: 10
A24: 22 | B24: Fase 1 - Fondasi & Divisi 2 (Service & Maintenance) | C24: Penyesuaian KPI & Work Log | D24: Backend Developer | E24: 3
A25: 23 | B25: Fase 2 - Keuangan & SDM | C25: Finance & Accounting: Entry Voucher, Cash & Bank, General Ledger | D25: Tech Lead / Senior Developer | E25: 12 | F25: Modul paling kompleks di seluruh SRS
A26: 24 | B26: Fase 2 - Keuangan & SDM | C26: Finance & Accounting: Accounts Payable, Accounts Receivable, Asset Management | D26: Tech Lead / Senior Developer | E26: 8
A27: 25 | B27: Fase 2 - Keuangan & SDM | C27: Finance & Accounting: Budgeting & Forecasting, Reporting & Analysis | D27: Tech Lead / Senior Developer | E27: 5
A28: 26 | B28: Fase 2 - Keuangan & SDM | C28: Invoice & Billing (nomor otomatis, PDF, partial payment, aging) | D28: Fullstack Developer (Livewire) | E28: 8
A29: 27 | B29: Fase 2 - Keuangan & SDM | C29: Kasbon/Cash Advance & Expense (approval 2 tahap, settlement) | D29: Fullstack Developer (Livewire) | E29: 8
A30: 28 | B30: Fase 2 - Keuangan & SDM | C30: Payroll (kalkulasi gaji, lembur, BPJS, PPh21, payslip, approval Direktur) | D30: Tech Lead / Senior Developer | E30: 12 | F30: Perlu validasi aturan BPJS/PPh21 final perusahaan sebelum development
A31: 29 | B31: Fase 2 - Keuangan & SDM | C31: Cost Control (dashboard budget vs actual, alert threshold, tarik data lintas modul) | D31: Fullstack Developer (Livewire) | E31: 8
A32: 30 | B32: Fase 2 - Keuangan & SDM | C32: Absensi/Attendance umum (check-in/out kantor, izin/cuti/sakit/alfa, integrasi payroll) | D32: Fullstack Developer (Livewire) | E32: 8 | F32: Terpisah dari Presensi GPS lapangan yang sudah ada (lihat temuan 3.4-ish, SRS 4.20)
A33: 31 | B33: Fase 3 - Divisi 1 (Sales & Pengadaan Pompa Baru) | C33: CRM & Sales Pipeline (leads, pipeline visual, log aktivitas, reminder, dashboard Marketing) | D33: Fullstack Developer (Livewire) | E33: 12
A34: 32 | B34: Fase 3 - Divisi 1 (Sales & Pengadaan Pompa Baru) | C34: Inventory Stok Pompa | D34: Fullstack Developer (Livewire) | E34: 4
A35: 33 | B35: Fase 3 - Divisi 1 (Sales & Pengadaan Pompa Baru) | C35: RFQ & BOQ Penjualan | D35: Fullstack Developer (Livewire) | E35: 6
A36: 34 | B36: Fase 3 - Divisi 1 (Sales & Pengadaan Pompa Baru) | C36: Penawaran Harga & Technical Data (approval, PDF, revisi) | D36: Fullstack Developer (Livewire) | E36: 8
A37: 35 | B37: Fase 3 - Divisi 1 (Sales & Pengadaan Pompa Baru) | C37: PO Masuk, BA Serah Terima, VDRL, Sales Order | D37: Fullstack Developer (Livewire) | E37: 10
A38: 36 | B38: Fase 4 - External-Facing & Cross-Cutting | C38: External Company Website (6 halaman, CMS, SEO, responsif) | D38: Frontend/Web Developer | E38: 18
A39: 37 | B39: Fase 4 - External-Facing & Cross-Cutting | C39: Client Portal (login, dashboard, progress real-time, dokumen, invoice read-only) | D39: Fullstack Developer (Livewire) | E39: 14
A40: 38 | B40: Fase 4 - External-Facing & Cross-Cutting | C40: SSO routing 3 portal (External/Client/Internal) | D40: Backend Developer | E40: 3
...

Sheet Rekap per Role
A1: Rekap Mandays & Estimasi Biaya per Role
A2: Isi kolom 'Tarif per Manday (Rp)' (sel kuning) sesuai standar rate internal perusahaan Anda.
A4: Role | B4: Total Mandays | C4: Tarif per Manday (Rp) | D4: Total Estimasi Biaya (Rp)
A5: Project Manager (Delivery) | B5: =SUMIF('Rincian Modul'!$D$3:$D$61,A5,'Rincian Modul'!$E$3:$E$61) -> 42 | C5: 0 | D5: =B5*C5 -> 0
A6: Tech Lead / Senior Developer | B6: =SUMIF('Rincian Modul'!$D$3:$D$61,A6,'Rincian Modul'!$E$3:$E$61) -> 109 | C6: 0 | D6: =B6*C6 -> 0
A7: Backend Developer | B7: =SUMIF('Rincian Modul'!$D$3:$D$61,A7,'Rincian Modul'!$E$3:$E$61) -> 36 | C7: 0 | D7: =B7*C7 -> 0
A8: Fullstack Developer (Livewire) | B8: =SUMIF('Rincian Modul'!$D$3:$D$61,A8,'Rincian Modul'!$E$3:$E$61) -> 170 | C8: 0 | D8: =B8*C8 -> 0
A9: Frontend/Web Developer | B9: =SUMIF('Rincian Modul'!$D$3:$D$61,A9,'Rincian Modul'!$E$3:$E$61) -> 18 | C9: 0 | D9: =B9*C9 -> 0
A10: UI/UX Designer | B10: =SUMIF('Rincian Modul'!$D$3:$D$61,A10,'Rincian Modul'!$E$3:$E$61) -> 15 | C10: 0 | D10: =B10*C10 -> 0
A11: QA / Tester | B11: =SUMIF('Rincian Modul'!$D$3:$D$61,A11,'Rincian Modul'!$E$3:$E$61) -> 38 | C11: 0 | D11: =B11*C11 -> 0
A12: Business Analyst | B12: =SUMIF('Rincian Modul'!$D$3:$D$61,A12,'Rincian Modul'!$E$3:$E$61) -> 22 | C12: 0 | D12: =B12*C12 -> 0
A13: DevOps / Infrastructure | B13: =SUMIF('Rincian Modul'!$D$3:$D$61,A13,'Rincian Modul'!$E$3:$E$61) -> 12 | C13: 0 | D13: =B13*C13 -> 0
A14: TOTAL | B14: =SUM(B5:B13) -> 462 | D14: =SUM(D5:D13) -> 0
A16: Catatan: Total Mandays ditarik otomatis (SUMIF) dari sheet 'Rincian Modul', termasuk baris overhead Project Management. Tarif per manday TIDAK diisi otomatis -- sesuaikan dengan standar gaji/vendor rate perusahaan.

Sheet Timeline
A1: Timeline Estimasi per Fase (SRS v2.0)
A2: Asumsi tim inti: 1 PM + 1 Tech Lead + 1 Backend Dev + 2-3 Fullstack Dev + 1 QA (+ Web Dev, UI/UX, BA, DevOps paruh waktu)
A4: Fase | B4: Deskripsi Singkat | C4: Role Terlibat | D4: Mandays Fase | E4: Estimasi Durasi (minggu)
A5: Fase 0 - Analisa & Desain | B5: Functional spec, ERD, arsitektur 3 portal, wireframe, sign-off | C5: BA, Tech Lead, UI/UX Designer | D5: =SUMIF('Rincian Modul'!$B$3:$B$61,A5,'Rincian Modul'!$E$3:$E$61) -> 43 | E5: 3
A6: Fase 1 - Fondasi & Divisi 2 (Service & Maintenance) | B6: Fondasi platform + rapikan Divisi 2 (Service & Maintenance) sesuai SRS, termasuk rekonsiliasi dgn sistem existing | C6: Tech Lead, Backend Dev, Fullstack Dev | D6: =SUMIF('Rincian Modul'!$B$3:$B$61,A6,'Rincian Modul'!$E$3:$E$61) -> 101 | E6: 5
A7: Fase 2 - Keuangan & SDM | B7: Finance & Accounting, Invoice, Kasbon/Expense, Payroll, Cost Control, Absensi umum | C7: Tech Lead, Fullstack Dev | D7: =SUMIF('Rincian Modul'!$B$3:$B$61,A7,'Rincian Modul'!$E$3:$E$61) -> 69 | E7: 4
A8: Fase 3 - Divisi 1 (Sales & Pengadaan Pompa Baru) | B8: Divisi 1: CRM, Sales Pipeline, Inventory, BOQ Penjualan, Sales Order | C8: Fullstack Dev | D8: =SUMIF('Rincian Modul'!$B$3:$B$61,A8,'Rincian Modul'!$E$3:$E$61) -> 40 | E8: 4
A9: Fase 4 - External-Facing & Cross-Cutting | B9: External Website, Client Portal, SSO 3 portal, Notification & Audit Trail, Dashboard per role | C9: Web Dev, Fullstack Dev, Backend Dev, Tech Lead | D9: =SUMIF('Rincian Modul'!$B$3:$B$61,A9,'Rincian Modul'!$E$3:$E$61) -> 61 | E9: 4
A10: Fase 5 - QA & Integrasi | B10: Test case, functional & regression & security testing, bug fixing, UAT | C10: QA, Backend Dev, Fullstack Dev | D10: =SUMIF('Rincian Modul'!$B$3:$B$61,A10,'Rincian Modul'!$E$3:$E$61) -> 74 | E10: 5
A11: Fase 6 - Deployment & Dokumentasi | B11: Infrastruktur produksi, deployment, dokumentasi, training | C11: DevOps, Tech Lead, Business Analyst | D11: =SUMIF('Rincian Modul'!$B$3:$B$61,A11,'Rincian Modul'!$E$3:$E$61) -> 32 | E11: 3
A12: TOTAL (bila fase berurutan penuh, tanpa overlap) | D12: =SUM(D5:D11) -> 420 | E12: =SUM(E5:E11) -> 28
A14: Catatan: total minggu di atas mengasumsikan fase berjalan strict berurutan (worst case), TIDAK termasuk mandays overhead Project Management (dihitung terpisah, lihat sheet Ringkasan). Dengan overlap wajar (mis. Fase 2 & 3 bisa mulai sebagian begitu fondasi Fase 1 selesai, QA berjalan incremental bukan hanya di Fase 5), durasi realistis untuk tim ~9-10 orang adalah 8-9 bulan kalender.
